<?xml version="1.0" ?>
<sdf version="1.4">
  <model name="carologistics-gripper">
    <static>false</static>
    <link name="gripper-hand">
      <gravity>false</gravity>
      <pose>0 0 0 0 0 0</pose>
      <!-- Origin is where the puck should be gripped -->
      <visual name="visual">
        <geometry>
          <mesh>
            <uri>model://carologistics/carologistics-gripper/meshes/gripper_base.dae</uri>
            <scale>0.001 0.001 0.001</scale>
          </mesh>
        </geometry>
        <material>
          <ambient>0.0 0.0 0.0 0.4</ambient>
        </material>
        <cast_shadows>false</cast_shadows>
      </visual>
      <inertial>
        <mass>0.1</mass>
      </inertial>
    </link>

    <link name="back-finger">
      <gravity>false</gravity>
      <pose>-0.0228 -0.0004 0.079 0 0 0</pose>
      <visual name="visual">
        <geometry>
          <mesh>
            <uri>model://carologistics/carologistics-gripper/meshes/back_finger.dae</uri>
            <scale>0.001 0.001 0.001</scale>
          </mesh>
        </geometry>
        <material>
          <ambient>0.0 0.0 0.0 0.4</ambient>
        </material>
        <cast_shadows>false</cast_shadows>
      </visual>
      <inertial>
        <mass>0.02</mass>
      </inertial>
      <collision name="collision-left">
        <pose>0.00207 0.01 -0.0506 0 0 -0.4</pose>
        <geometry>
          <box>
            <size>0.00425 0.0095 0.06</size>
          </box>
        </geometry>
      </collision>
      <collision name="collision-middle">
        <pose>-0.00007 0.0002 -0.0506 0 0 0</pose>
        <geometry>
          <box>
            <size>0.00425 0.0083 0.06</size>
          </box>
        </geometry>
      </collision>
      <collision name="collision-right">
        <pose>0.00207 -0.0096 -0.0506 0 0 0.4</pose>
        <geometry>
          <box>
            <size>0.00425 0.0095 0.06</size>
          </box>
        </geometry>
      </collision>
    </link>
    <joint name="back-finger-hinge" type="revolute">
      <pose>0 0 0 0 0 0</pose>
      <parent>gripper-hand</parent>
      <child>back-finger</child>
      <axis>
        <xyz>0 1 0</xyz>
        <limit>
          <lower>0</lower>
          <upper>0.349066</upper>
          <effort>30</effort>
          <velocity>1.0</velocity>
        </limit>
      </axis>
    </joint>

    <link name="left-finger">
      <gravity>false</gravity>
      <pose>0.0102 0.0192 0.078 0 0 1.04719</pose>
      <visual name="visual">
        <geometry>
          <mesh>
            <uri>model://carologistics/carologistics-gripper/meshes/finger.dae</uri>
            <scale>0.001 0.001 0.001</scale>
          </mesh>
        </geometry>
        <material>
          <ambient>0.0 0.0 0.0 0.4</ambient>
        </material>
        <cast_shadows>false</cast_shadows>
      </visual>
      <inertial>
        <mass>0.02</mass>
      </inertial>
      <collision name="collision">
        <pose>0 0 -0.0496 0 0 0</pose>
        <geometry>
          <box>
            <size>0.004 0.0092 0.06</size>
          </box>
        </geometry>
      </collision>
    </link>
    <joint name="left-finger-hinge" type="revolute">
      <pose>0 0 0 0 0 1.04719</pose>
      <parent>gripper-hand</parent>
      <child>left-finger</child>
      <axis>
        <xyz>0 1 0</xyz>
        <limit>
          <lower>0</lower>
          <upper>0.2618</upper>
          <effort>30</effort>
          <velocity>1.0</velocity>
        </limit>
      </axis>
    </joint>

    <link name="right-finger">
      <gravity>false</gravity>
      <pose>0.0102 -0.0192 0.078 0 0 -1.04719</pose>
      <visual name="visual">
        <geometry>
          <mesh>
            <uri>model://carologistics/carologistics-gripper/meshes/finger.dae</uri>
            <scale>0.001 0.001 0.001</scale>
          </mesh>
        </geometry>
        <material>
          <ambient>0.0 0.0 0.0 0.4</ambient>
        </material>
        <cast_shadows>false</cast_shadows>
      </visual>
      <inertial>
        <mass>0.02</mass>
      </inertial>
      <collision name="collision">
        <pose>0 0 -0.0496 0 0 0</pose>
        <geometry>
          <box>
            <size>0.004 0.0092 0.06</size>
          </box>
        </geometry>
      </collision>
    </link>
    <joint type="revolute" name="right-finger-hinge">
      <pose>0 0 0 0 0 0</pose>
      <parent>gripper-hand</parent>
      <child>right-finger</child>
      <axis>
        <xyz>0 1 0</xyz>
        <limit>
          <lower>0</lower>
          <upper>0.2618</upper>
          <effort>30</effort>
          <velocity>1.0</velocity>
        </limit>
      </axis>
    </joint>

    <plugin name="Gripper" filename="libgripper.so"/>
  </model>
</sdf>
